Workbook
Name Economic: Drop_down_coding!$E$44:$E$51
Name Feature: Drop_down_coding!$E$54:$E$61
Name Legal: Drop_down_coding!$N$44:$N$51
Name Market.Pulse: Drop_down_coding!$E$19:$E$28
Name Market_Pulse: Drop_down_coding!$B$33:$B$37
Name Marketing: Drop_down_coding!$H$54:$H$61
Name Partnership: Drop_down_coding!$K$54:$K$61
Name Players.Movement: Drop_down_coding!$H$19:$H$28
Name Players_Movement: Drop_down_coding!$E$33:$E$38
Name Political: Drop_down_coding!$B$44:$B$51
Name Product: Drop_down_coding!$B$54:$B$61
Name Slicer_category: #N/A
Name Slicer_signal_level: #N/A
Name Slicer_sub_topic_group: #N/A
Name Slicer_subcategory: #N/A
Name Slicer_topic_group: #N/A
Name Slicer_week: #N/A
Name Social: Drop_down_coding!$H$44:$H$51
Name Strategy: Drop_down_coding!$N$54:$N$61
Name Technology: Drop_down_coding!$K$44:$K$51
Name topic_group: Drop_down_coding!$B$19:$B$20

Sheet NGUYÊN TẮC
A1: NGUYÊN TẮC CHUNG
A2: Market Watch hướng tới target audience là Product/ Kinh doanh/ Marketing/ Growth/ CX - CEE nắm bắt được tình hình thị trường liên quan đến V-App theo 7 vertical chính: AI - Chat - E-commerce - Travel (khách sạn/ vui chơi giải trí) - Ride/ Food Delivery - E-wallet - Ticket (sự kiện, concert,...) - Nhận diện mô hình / xu hướng - Dự đoán (đón trước) hành động của đối thủ - Chuẩn bị chính sách - Thích nghi với công nghệ - Ra quyết định về Marketing / Tăng trưởng / Trải nghiệm khách hàng (CX)
A3: 2 streams chính - Market Pulse - Tín hiệu thị trường về chính sách, công nghệ, đối thủ adjacent, xu hướng - Players Movement - Hành động cụ thể của các players theo từng verticals tại Việt Nam
A4: Tracked players: | B4: MoMo; Zalo; ZaloPay; Grab; Traveloka; Shopee; TikTok Shop; WhatsApp; Telegram; WeChat; AliPay
A5: Adjacent players: | B5: GoTo; Gojek; Sea; Lazada; Tiki; Sendo; Be; Xanh SM; Green SM; ViettelPay; VNPAY; ShopeePay; Apple Pay; Google Pay; WeChat Pay; Ant; Stripe; PayPal; Uber; DoorDash; Bolt; Meta; Threads; Instagram; ByteDance; Anthropic; OpenAI; Google; Apple
A7: Danh sách sheet
A8: Sheet name | B8: Mục đích
A9: Soure_Crawl_Data | B9: Tổng hợp tất các source để crawl bài viết
A10: Scanning | B10: Nguyên tắc lọc bài viết - Round 1 dựa trên title/ short description
A11: Grading | B11: Nguyên tắc chấm điểm bài viết theo tiêu chí để lọc bài viết - Roudn 2 dựa trên nội dung bài viết
A12: Coding | B12: Nguyên tắc phân loại bài viết theo Topic/ Category/ Verticals
A13: Database | B13: Tổng hợp tất cả các bài viết chi tiết
A15: THAO TÁC CHÍNH
A16: Bước | B16: Deliverable | C16: Rule/ Reference sheet
A17: Bước 1 - Crawl data
A18: Truy cập link bài viết trong Source_Crawl_Data | B18: orginal_orginal_source | C18: Source_Crawl_Data
A19: Scan để lọc bài viết thỏa mãn (1) thời gian đăng bài thuộc thời gian tracking (1) tiêu đều/short description chứa keywords | B19: url | C19: Source_Crawl_Data: tracking week Scanning: keyword
A20: Tổng hợp lại trong Database thỏa mãn điều kiện | B20: excel
A22: Bước 2 - AI phân loại tin tức, viết title_normalized và summary
A23: Gửi danh sách url đã tổng hợp ở B1 cho AI | B23: Lọc URL có trùng nội dung Xóa URL từ các nguồn báo có độ uy tín thấp hơn/ hoặc ít nội dung hơn và giữa URL của nguồn báo có độ uy tín cao hơn/ hoặc đầy đủ nội dung hơn
A24: AI trả lại file excel đầy đủ các trường thông tin | B24: source_name | C24: fetch từ url
B25: URL | C25: fetch từ bài viết
B26: week | C26: theo craw_date
B27: publish_date | C27: fetch từ bài viết
B28: topic_group | C28: Coding B2
B29: sub_topic_group | C29: Coding B2
B30: category | C30: Coding B3
B31: subcategory | C31: Coding B4
B32: related _vertical | C32: Coding B5
B33: title_normalized | C33: Updating
B34: summary | C34: Updating
B35: start-date | C35: fetch từ bài viết: thời gian diễn ra chương trình, bắt đầu từ, hiệu lực từ, ra mắt từ
B36: end-date | C36: fetch từ bài viết: kết thúc vào, hết hiệu lực từ, đóng sản phẩm từ,
... B39: title_raw | C39: fetch từ bài viết
A41: Bước 3 - Quality control
A42: Input vào database | B42: Clean database
A43: Review về cách grading | B43: Clean database
A44: Review title_normalized và summary | B44: Clean database

Sheet Source_Crawl_Data
A1: week_start | B1: 46144
A2: week_end | B2: =B1+6 -> 46150 | C2: =WEEKNUM(B2,2) -> 19
A5: no | B5: topic_group | C5: source_name | D5: chuyên mục | E5: original_source_url | F5: source_url | G5: overview | H5: characteristics | I5: method | J5: note | K5: extract_source | L5: date_edit | M5: Column1 | N5: Column2 | O5: Column3
A6: 1 | B6: Market Purlse | C6: GenK | D6: AI | E6: https://genk.vn/ai.chn | F6: =_xlfn.TEXTJOIN("-",TRUE,K6&M6,N6,O6)&".chn" -> https://genk.vn/ai/2-5-2026.chn | G6: - Trang chuyên mục riêng để cập nhật về AI (ai.html) - Có thể filter để xem theo ngày | H6: Timestamp trong UI hiển thị published_date = bao nhiêu ngày trước | I6: - Quét theo timestamp hiển thị trên UI 1-8 ngày trước - Hoặc tự động gen URL bằng cách điều chỉnh trong URL sau /23-2-2026 theo từng ngày trong tuần tracking | J6: theo ngày | K6: https://genk.vn/ai/ | L6: =B1 -> 46144 | M6: =DAY(L6) -> 2 | N6: =MONTH(L6) -> 5 | O6: =YEAR(L6) -> 2026
A7: 2 | B7: Market Purlse | C7: GenK | D7: Tin ICT | E7: https://genk.vn/tin-ict.chn | F7: =_xlfn.TEXTJOIN("-",TRUE,K7&M7,N7,O7)&".chn" -> https://genk.vn/tin-ict/2-5-2026.chn | G7: - Trang chuyên mục riêng để cập nhật về tin ICT - Có thể filter để xem theo ngày | H7: Timestamp trong UI hiển thị published_date = bao nhiêu ngày trước | I7: - Quét theo timestamp hiển thị trên UI 1-8 ngày trước - Hoặc tự động gen URL bằng cách điều chỉnh trong URL sau /23-2-2026 theo từng ngày trong tuần tracking | J7: theo ngày | K7: https://genk.vn/tin-ict/ | L7: =B1 -> 46144 | M7: =DAY(L7) -> 2 | N7: =MONTH(L7) -> 5 | O7: =YEAR(L7) -> 2026
A8: 3 | B8: Market Purlse | C8: Báo tin tức | D8: Thị trường tiền tệ | E8: https://baotintuc.vn/thi-truong-tien-te-587ct128.htm | F8: =_xlfn.TEXTJOIN("-",TRUE,K8&M8,N8,O8)&".htm" -> https://baotintuc.vn/thi-truong-tien-te-587ct128/d2-5-2026.htm | G8: Trang chuyên mục riêng về thị trường tiền tệ | H8: Không có timestamp trên UI. Published_date có thể điều chỉnh tại timestamp trong URL với cấu trúc /d23-2-26 | I8: Gen URL bằng cách điều chỉnh slug /d23-2-26 theo từng ngày trong tuần tracking | J8: theo ngày | K8: https://baotintuc.vn/thi-truong-tien-te-587ct128/d | L8: =B1 -> 46144 | M8: =DAY(L8) -> 2 | N8: =MONTH(L8) -> 5 | O8: =YEAR(L8) -> 2026
A9: 4 | B9: Market Purlse | C9: VNEconomy | D9: Techconnect | E9: https://vneconomy.vn/techconnect/ | F9: =E9 -> https://vneconomy.vn/techconnect/ | G9: - Trang chuyên mục riêng về công nghệ - Tagging theo 3 chuyên mục con: Techtalk, Techlifstyle, Kính lúp công nghệ | H9: Timestap trong UI hiển thị published_date = hh:mm dd/mm/yyyy | I9: Quét theo timestamp hiển thị trên UI mãn thời gian tracking | J9: không filter
A10: 5 | B10: Market Purlse | C10: VNEconomy | D10: Techlifestyle | E10: https://vneconomy.vn/techconnect/tech-lifestyle.htm | F10: =E10 -> https://vneconomy.vn/techconnect/tech-lifestyle.htm | G10: Chuyên mục con chuyên chủ đề xoay quanh Techlifestyle | H10: Timestamp trong UI hiển thị published_date = hh:mm dd/mm/yyyy | I10: Quét theo timestamp hiển thị trên UI của trang chuyên mục thỏa mãn thời gian tracking | J10: không filter
A11: 6 | B11: Market Purlse | C11: VNEconomy | D11: Techtalk | E11: https://vneconomy.vn/techconnect/tech-talk.htm | F11: =E11 -> https://vneconomy.vn/techconnect/tech-talk.htm | G11: Chuyên mục con chuyên chủ đề xoay quanh TechTalk | H11: Timestamp trong UI hiển thị published_date = hh:mm dd/mm/yyyy | I11: Quét theo timestamp hiển thị trên UI của trang chuyên mục thỏa mãn thời gian tracking | J11: không filter
A12: 7 | B12: Market Purlse | C12: Dân Trí | D12: AI - Internet | E12: https://dantri.com.vn/cong-nghe/ai-internet/from/2026-02-23/to/2026-02-23.htm | F12: =K12&"from/"&N12&"/to/"&O12&".htm" -> https://dantri.com.vn/cong-nghe/ai-internet/from/2026-05-02/to/2026-05-08.htm | G12: - Trang chuyên mục riêng về AI - Cho phép filter theo ngày để lọc theo tuần | H12: Không có timestamp trên UI. Có thể điều chỉnh thời gian tracking trên URL tại /from/2026-02-23/to/2026-02-23 | I12: Gen URL qua query string trong URL /from/2026-02-23/to/2026-02-23 | J12: theo tuần | K12: https://dantri.com.vn/cong-nghe/ai-internet/ | L12: =B1 -> 46144 | M12: =L12+6 -> 46150 | N12: =TEXT(L12,"yyyy-mm-dd") -> 2026-05-02 | O12: =TEXT(M12,"yyyy-mm-dd") -> 2026-05-08
A13: 8 | B13: Market Purlse | C13: Dân Trí | D13: An ninh mạng | E13: https://dantri.com.vn/cong-nghe/an-ninh-mang.htm | F13: =K13&"from/"&N13&"/to/"&O13&".htm" -> https://dantri.com.vn/cong-nghe/an-ninh-mang/from/2026-05-02/to/2026-05-08.htm | G13: - Trang chuyên mục riêng về an ninh mạng - Cho phép filter theo ngày để lọc theo tuần | H13: Không có timestamp trên UI. Có thể điều chỉnh thời gian tracking trên URL tại /from/2026-02-23/to/2026-02-23 | I13: Gen URL qua query string trong URL /from/2026-02-23/to/2026-02-23 | J13: theo tuần | K13: https://dantri.com.vn/cong-nghe/an-ninh-mang/ | L13: =B1 -> 46144 | M13: =L13+6 -> 46150 | N13: =TEXT(L13,"yyyy-mm-dd") -> 2026-05-02 | O13: =TEXT(M13,"yyyy-mm-dd") -> 2026-05-08
A14: 9 | B14: Market Purlse | C14: VNExpress | D14: Khoa học công nghệ | E14: https://vnexpress.net/khoa-hoc-cong-nghe | F14: =K14&"fromdate/"&N14&"/todate/"&O14&"/allcate/1006219" -> https://vnexpress.net/category/day/cateid/1006219/fromdate/1777680000/todate/1778198400/allcate/1006219 | G14: - Trang chuyên mục riêng về khoa học công nghệ - Cho phép filter theo ngày để lọc theo tuần | H14: - Không có timestamp trên UI - Có thể điều chỉnh thời gian tracking trên URL tại /fromdate/1771804800/todate/1772323200/ - Timestamp trên URL hiển thị theo dạng Unix Timestamp | I14: Gen URL qua query string trong URL /fromdate/1771804800/todate/1772323200/ | J14: theo tuần | K14: https://vnexpress.net/category/day/cateid/1006219/ | L14: =B1 -> 46144 | M14: =L14+6 -> 46150 | N14: =(L14-DATE(1970,1,1))*86400 -> 1777680000 | O14: =(M14-DATE(1970,1,1))*86400 -> 1778198400
A15: 10 | B15: Market Purlse | C15: Bloomberg | D15: Consumer tech | E15: https://www.bloomberg.com/technology/consumer-tech | F15: =E15 -> https://www.bloomberg.com/technology/consumer-tech | G15: - Trang chuyên mục về những xu hướng công nghệ liên quan đến người dùng - AISAN edition | H15: Timestamp trong UI hiển thị published_date = Tháng Ngày, Năm | I15: - Quét theo timestamp hiển thị trên UI | J15: không filter
A16: 11 | B16: Market Purlse | C16: Tech in Asia | D16: Fintech | E16: https://www.techinasia.com/category/fintech | F16: =E16 -> https://www.techinasia.com/category/fintech | G16: - Trang chuyên mục về những xu hướng liên quan đến thị trường fintech | H16: Timestamp trong UI hiển thị published_date = Tháng Ngày, Năm | I16: - Quét theo timestamp hiển thị trên UI | J16: không filter
A17: 12 | B17: Market Purlse | C17: Tech Crunch | D17: Apps | E17: https://techcrunch.com/category/apps/ | F17: =E17 -> https://techcrunch.com/category/apps/ | G17: - Trang chuyên mục về những xu hướng liên quan đến App | H17: Timestamp trong UI hiển thị published_date = bao nhiêu ngày trước | I17: - Quét theo timestamp hiển thị trên UI 1-8 ngày trước | J17: không filter
A18: 13 | B18: Market Purlse | C18: Thư viện pháp luật | D18: Văn bản mới | E18: https://thuvienphapluat.vn/page/tim-van-ban.aspx?keyword=nhnn&area=0&type=0&status=0&lan=1&org=0&signer=0&match=True&sort=1&bdate=31/12/2025&edate=31/12/2025 | F18: =TEXT(K18&"&bdate="&N18&"&edate="&O18,0) -> https://thuvienphapluat.vn/page/tim-van-ban.aspx?keyword=nhnn&area=0&type=0&status=0&lan=1&org=0&signer=0&match=True&sort=1&bdate=02-05-2026&edate=08-05-2026 | G18: - Chuyên trang cập nhập các văn bản pháp luận mới - Cho phép filter theo khoảng thời gian ban hành, loại văn bản, cơ quan ban hành, keyword (lọc văn bản thuộc phạm trù nội dung mong muốn) | H18: - Không có timestamp trên UI - Điều chỉnh keyword tại keyword=nhnn - Có thể điều chỉnh thời gian tracking trên URL tại bdate=23-02-2026&edate=01-03-2026 | I18: - Gen URL qua query string trong URL bdate=23-02-2026&edate=01-03-2026 - Điều chỉnh query string để lọc từ khóa cần thiết keyword=nhnn | J18: theo tuần | K18: https://thuvienphapluat.vn/page/tim-van-ban.aspx?keyword=nhnn&area=0&type=0&status=0&lan=1&org=0&signer=0&match=True&sort=1 | L18: =B1 -> 46144 | M18: =L18+6 -> 46150 | N18: =TEXT(L18,"dd-mm-yyyy") -> 02-05-2026 | O18: =TEXT(M18,"dd-mm-yyyy") -> 08-05-2026
A19: 14 | B19: Market Purlse | C19: Luật Việt Nam | D19: Điểm tin chính sách | E19: https://luatvietnam.vn/ban-tin-luatvietnam/diem-tin-chinh-sach-moi-c559-article.html | F19: =E19 -> https://luatvietnam.vn/ban-tin-luatvietnam/diem-tin-chinh-sach-moi-c559-article.html | G19: - Chuyên trang tổng hợp chính sách mới hàng tháng bao gồm chính sách mới và danh sách văn bản có hiệu từng tháng - Hiển thị rõ ràng tháng trong UI - Trong trang danh sách văn bản có hiệu lực có ngày ban hành (BH), ngày hiệu lực (HL) đầy đủ và phân theo thể loại văn bản | H19: Có thông tin tháng ban hành trên UI | I19: - Tìm kiếm chính sách mới/danh sách văn bản theo tháng - Quét theo ngày hiệu lực (HL) và keyword liên quan để xem có chính sách nào mới sắp có hiệu lực trong tuần tiếp theo | J19: không filter
A20: 15 | B20: Market Purlse | C20: Luật Việt Nam | D20: Văn bản mới | E20: https://luatvietnam.vn/ban-tin-luatvietnam/diem-tin-van-ban-moi-c220-article.html | F20: =E20 -> https://luatvietnam.vn/ban-tin-luatvietnam/diem-tin-van-ban-moi-c220-article.html | G20: - Chuyên trang điểm tin văn bản mới hàng tuần theo từng số - Trong trang điểm tin được phân loại theo lĩnh vực | H20: Chỉ có thông tin số văn bản trên UI | I20: Tìm kiếm bản tin theo số văn bản mới nhất | J20: không filter
A21: 16 | B21: Players Movement | C21: ZaloPay website | D21: Tin tức | E21: https://zalopay.vn/tin-tuc | F21: =E21 -> https://zalopay.vn/tin-tuc
A22: 17 | B22: Players Movement | C22: ZaloPay website | D22: Khuyến mãi | E22: https://zalopay.vn/khuyen-mai | F22: =E22 -> https://zalopay.vn/khuyen-mai
A23: 18 | B23: Players Movement | C23: ZaloOA website | D23: Tin tức | E23: https://oa.zalo.me/home/resources/news | F23: =E23 -> https://oa.zalo.me/home/resources/news
A24: 19 | B24: Players Movement | C24: MoMo wesbite | D24: Tin tức | E24: https://www.momo.vn/tin-tuc | F24: =E24 -> https://www.momo.vn/tin-tuc
A25: 20 | B25: Players Movement | C25: WhatsApp website | D25: Blog | E25: https://blog.whatsapp.com/ | F25: =E25 -> https://blog.whatsapp.com/
A26: 21 | B26: Players Movement | C26: Telegram website | D26: Blog | E26: https://telegram.org/blog | F26: =E26 -> https://telegram.org/blog
A27: 22 | B27: Players Movement | C27: Shopee | D27: Blog | E27: https://banhang.shopee.vn/edu/category?sub_cat_id=1006 | F27: =E27 -> https://banhang.shopee.vn/edu/category?sub_cat_id=1006
A28: 23 | B28: Players Movement | C28: TiktokShop | D28: Blog | E28: https://seller-vn.tiktok.com/university/essay?knowledge_id=8858869405370113 | F28: =E28 -> https://seller-vn.tiktok.com/university/essay?knowledge_id=8858869405370113
A29: 24 | B29: Players Movement | C29: Grab Merchant | D29: Blog | E29: https://merchant.grab.com/vn-vn/blog | F29: =E29 -> https://merchant.grab.com/vn-vn/blog
A30: 25 | B30: Players Movement | C30: Grab Passenger | D30: Blog | E30: https://www.grab.com/vn/blog/ | F30: =E30 -> https://www.grab.com/vn/blog/
A31: 26 | B31: Market Purlse | C31: Techinasia | D31: Consumer tech | E31: https://www.techinasia.com/category/consumer-tech | F31: =E31 -> https://www.techinasia.com/category/consumer-tech
A32: 27 | B32: Market Purlse | C32: Techinasia | D32: E-commerce | E32: https://www.techinasia.com/category/e-commerce-social-commerce | F32: =E32 -> https://www.techinasia.com/category/e-commerce-social-commerce
A33: 28 | B33: Market Purlse | C33: SCMP | D33: Tech | E33: https://www.scmp.com/tech | F33: =E33 -> https://www.scmp.com/tech
A34: 29 | B34: Market Purlse | C34: VNExpress | D34: Kinh doanh | E34: https://vnexpress.net/kinh-doanh | F34: =K34&"fromdate/"&N34&"/todate/"&O34&"/allcate/1006219" -> https://vnexpress.net/category/day/cateid/1003159/fromdate/1777680000/todate/1778198400/allcate/1006219 | K34: https://vnexpress.net/category/day/cateid/1003159/ | L34: =B1 -> 46144 | M34: =L34+6 -> 46150 | N34: =(L34-DATE(1970,1,1))*86400 -> 1777680000 | O34: =(M34-DATE(1970,1,1))*86400 -> 1778198400
B37: Market Purlse | C37: Baotintuc | E37: https://baotintuc.vn/thi-truong-tien-te-587ct128.htm | F37: =_xlfn.TEXTJOIN("-",TRUE,K37&M37,N37,O37)&".htm" -> https://baotintuc.vn/thi-truong-tien-te-587ct128/d3-5-2026.htm | G37: Trang chuyên mục riêng về thị trường tiền tệ | H37: Không có timestamp trên UI. Published_date có thể điều chỉnh tại timestamp trong URL với cấu trúc /d23-2-26 | I37: - Tự động gen URL bằng cách điều chỉnh trong URL sau /d23-2-26 theo từng ngày trong tuần tracking - Quét và tổng hợp thông tin theo từng URL | K37: https://baotintuc.vn/thi-truong-tien-te-587ct128/d | L37: =B1+1 -> 46145 | M37: =DAY(L37) -> 3 | N37: =MONTH(L37) -> 5 | O37: =YEAR(L37) -> 2026
B38: Market Purlse | C38: Baotintuc | E38: https://baotintuc.vn/thi-truong-tien-te-587ct128.htm | F38: =_xlfn.TEXTJOIN("-",TRUE,K38&M38,N38,O38)&".htm" -> https://baotintuc.vn/thi-truong-tien-te-587ct128/d4-5-2026.htm | G38: Trang chuyên mục riêng về thị trường tiền tệ | H38: Không có timestamp trên UI. Published_date có thể điều chỉnh tại timestamp trong URL với cấu trúc /d23-2-26 | I38: - Tự động gen URL bằng cách điều chỉnh trong URL sau /d23-2-26 theo từng ngày trong tuần tracking - Quét và tổng hợp thông tin theo từng URL | K38: https://baotintuc.vn/thi-truong-tien-te-587ct128/d | L38: =L37+1 -> 46146 | M38: =DAY(L38) -> 4 | N38: =MONTH(L38) -> 5 | O38: =YEAR(L38) -> 2026
B39: Market Purlse | C39: Baotintuc | E39: https://baotintuc.vn/thi-truong-tien-te-587ct128.htm | F39: =_xlfn.TEXTJOIN("-",TRUE,K39&M39,N39,O39)&".htm" -> https://baotintuc.vn/thi-truong-tien-te-587ct128/d5-5-2026.htm | G39: Trang chuyên mục riêng về thị trường tiền tệ | H39: Không có timestamp trên UI. Published_date có thể điều chỉnh tại timestamp trong URL với cấu trúc /d23-2-26 | I39: - Tự động gen URL bằng cách điều chỉnh trong URL sau /d23-2-26 theo từng ngày trong tuần tracking - Quét và tổng hợp thông tin theo từng URL | K39: https://baotintuc.vn/thi-truong-tien-te-587ct128/d | L39: =L38+1 -> 46147 | M39: =DAY(L39) -> 5 | N39: =MONTH(L39) -> 5 | O39: =YEAR(L39) -> 2026
B40: Market Purlse | C40: Baotintuc | E40: https://baotintuc.vn/thi-truong-tien-te-587ct128.htm | F40: =_xlfn.TEXTJOIN("-",TRUE,K40&M40,N40,O40)&".htm" -> https://baotintuc.vn/thi-truong-tien-te-587ct128/d6-5-2026.htm | G40: Trang chuyên mục riêng về thị trường tiền tệ | H40: Không có timestamp trên UI. Published_date có thể điều chỉnh tại timestamp trong URL với cấu trúc /d23-2-26 | I40: - Tự động gen URL bằng cách điều chỉnh trong URL sau /d23-2-26 theo từng ngày trong tuần tracking - Quét và tổng hợp thông tin theo từng URL | K40: https://baotintuc.vn/thi-truong-tien-te-587ct128/d | L40: =L39+1 -> 46148 | M40: =DAY(L40) -> 6 | N40: =MONTH(L40) -> 5 | O40: =YEAR(L40) -> 2026
B41: Market Purlse | C41: Baotintuc | E41: https://baotintuc.vn/thi-truong-tien-te-587ct128.htm | F41: =_xlfn.TEXTJOIN("-",TRUE,K41&M41,N41,O41)&".htm" -> https://baotintuc.vn/thi-truong-tien-te-587ct128/d7-5-2026.htm | G41: Trang chuyên mục riêng về thị trường tiền tệ | H41: Không có timestamp trên UI. Published_date có thể điều chỉnh tại timestamp trong URL với cấu trúc /d23-2-26 | I41: - Tự động gen URL bằng cách điều chỉnh trong URL sau /d23-2-26 theo từng ngày trong tuần tracking - Quét và tổng hợp thông tin theo từng URL | K41: https://baotintuc.vn/thi-truong-tien-te-587ct128/d | L41: =L40+1 -> 46149 | M41: =DAY(L41) -> 7 | N41: =MONTH(L41) -> 5 | O41: =YEAR(L41) -> 2026
B42: Market Purlse | C42: Baotintuc | E42: https://baotintuc.vn/thi-truong-tien-te-587ct128.htm | F42: =_xlfn.TEXTJOIN("-",TRUE,K42&M42,N42,O42)&".htm" -> https://baotintuc.vn/thi-truong-tien-te-587ct128/d8-5-2026.htm | G42: Trang chuyên mục riêng về thị trường tiền tệ | H42: Không có timestamp trên UI. Published_date có thể điều chỉnh tại timestamp trong URL với cấu trúc /d23-2-26 | I42: - Tự động gen URL bằng cách điều chỉnh trong URL sau /d23-2-26 theo từng ngày trong tuần tracking - Quét và tổng hợp thông tin theo từng URL | K42: https://baotintuc.vn/thi-truong-tien-te-587ct128/d | L42: =L41+1 -> 46150 | M42: =DAY(L42) -> 8 | N42: =MONTH(L42) -> 5 | O42: =YEAR(L42) -> 2026
B43: Market Purlse | C43: GenK | E43: https://genk.vn/ai.chn | F43: =_xlfn.TEXTJOIN("-",TRUE,K43&M43,N43,O43)&".chn" -> https://genk.vn/ai/3-5-2026.chn | G43: - Trang chuyên mục riêng để cập nhật về AI (ai.html) - Có thể filter để xem theo ngày | H43: Timestamp trong UI hiển thị published_date = bao nhiêu ngày trước | I43: - Quét theo timestamp hiển thị trên UI 1-8 ngày trước - Hoặc tự động gen URL bằng cách điều chỉnh trong URL sau /23-2-2026 theo từng ngày trong tuần tracking | K43: https://genk.vn/ai/ | L43: =B1+1 -> 46145 | M43: =DAY(L43) -> 3 | N43: =MONTH(L43) -> 5 | O43: =YEAR(L43) -> 2026
B44: Market Purlse | C44: GenK | E44: https://genk.vn/ai.chn | F44: =_xlfn.TEXTJOIN("-",TRUE,K44&M44,N44,O44)&".chn" -> https://genk.vn/ai/4-5-2026.chn | K44: https://genk.vn/ai/ | L44: =L43+1 -> 46146 | M44: =DAY(L44) -> 4 | N44: =MONTH(L44) -> 5 | O44: =YEAR(L44) -> 2026
...

Sheet Source_Crawl_Data (2)
A1: week_start | B1: 46130
A2: week_end | B2: 46136 | C2: 17
A4: no | B4: priority | C4: source_name | D4: chuyên mục | E4: original_source_url
A5: 1 | B5: 0 | C5: Grab Merchant | D5: Blog | E5: https://merchant.grab.com/vn-vn/blog
A6: 2 | B6: 0 | C6: Grab Passenger | D6: Blog | E6: https://www.grab.com/vn/blog/
A7: 3 | B7: 0 | C7: Grab Passenger | D7: Inside Grab | E7: https://www.grab.com/inside-grab/
A8: 4 | B8: 0 | C8: MoMo wesbite | D8: Tin tức | E8: https://www.momo.vn/tin-tuc
A9: 5 | B9: 0 | C9: Shopee | D9: Blog | E9: https://banhang.shopee.vn/edu/category?sub_cat_id=1006
A10: 6 | B10: 0 | C10: Telegram website | D10: Blog | E10: https://telegram.org/blog
A11: 7 | B11: 0 | C11: TiktokShop | D11: Blog | E11: https://seller-vn.tiktok.com/university/essay?knowledge_id=8858869405370113
A12: 8 | B12: 0 | C12: WhatsApp website | D12: Blog | E12: https://blog.whatsapp.com/
A13: 9 | B13: 0 | C13: ZaloOA website | D13: Tin tức | E13: https://oa.zalo.me/home/resources/news
A14: 10 | B14: 0 | C14: ZaloPay website | D14: Tin tức | E14: https://zalopay.vn/tin-tuc
A15: 11 | B15: 0 | C15: ZaloPay website | D15: Khuyến mãi | E15: https://zalopay.vn/khuyen-mai
A16: 12 | B16: 1 | C16: Bloomberg | D16: Consumer tech | E16: https://www.bloomberg.com/technology/consumer-tech
... A38: 34 | B38: 3 | C38: The Information | D38: Tech | E38: https://www.theinformation.com/technology?view=recent

Sheet Scanning
A1: KEY WORDS SCAN TITLE/SHORT DESCRIPTION
A2: Title/ short description cần chưa ít nhất 1 keywords thuộc 1 trong 2 cluster dưới và không match với bất kỳ exclude pattern nào
A4: Cluster 1 - Players
A5: Tracked players: | B5: MoMo; Zalo; ZaloPay; Grab; Traveloka; Shopee; TikTok Shop; WhatsApp; Telegram; WeChat; AliPay
A6: Adjacent players: | B6: GoTo; Gojek; Sea; Lazada; Tiki; Sendo; Be; Xanh SM; Green SM; ViettelPay; VNPAY; ShopeePay; Apple Pay; Google Pay; WeChat Pay; Ant; Stripe; PayPal; Uber; DoorDash; Bolt; Meta; Threads; Instagram; ByteDance; Anthropic; OpenAI; Google; Apple
A8: Cluster 2 - Vertical keywords
A9: Vertical | B9: Keywords
A10: E-wallet | B10: ví điện tử; e-wallet; payment; thanh toán; QR; thanh toán quốc tế; QR quốc tế; BNPL; trả sau; kiều hối; remittance; fintech; mobile payment; tích hợp crypto; tích hợp tiền mã hóa;
A11: Ride / Delivery | B11: ride-hailing; gọi xe; food delivery; giao đồ ăn; mobility; last-mile; courier; gig economy
A12: TMĐT | B12: e-commerce; TMĐT; marketplace; seller fee; GMV; social commerce; D2C
A13: AI | B13: AI agent; LLM; GenAI; chatbot AI; voice AI; ChatGPT; Gemini; Claude; DeepSeek; AI assistant
A14: Chat | B14: messenger; chat app; social chat; super-app chat; mini app; mini program
A15: Travel | B15: OTA; booking; khách sạn; vé máy bay; tour; du lịch; travel; hotel
A16: Ticket | B16: nền tảng bán vé; hợp tác bán vé; Ticketbox; TicketMaster; Ticketgo; CTTicket
A18: EXCLUDE PATTERNS
A19: Pattern | B19: Ví dụ
A20: HR/layoff thuần, không gắn product | B20: "Startup AI sa thải 25% nhân sự để 'thuần AI'" → loại. (Có chữ AI nhưng không có lesson cho TA)
A21: AI research / paper academic | B21: "Mô hình mới đạt 92% benchmark MMLU", "DeepMind công bố paper về chain-of-thought"
A22: Dev tooling thuần B2D | B22: "OpenAI Agents SDK update", "LangChain v0.3 ra mắt", API/SDK release không có B2C app
A23: Stock price / earnings | B23: "Cổ phiếu Y tăng 5% sau Q2 earnings" Tin tài chính/đầu tư thuần túy (stocks, earnings không liên quan platform)
A24: Personality/celeb news không kèm action | B24: "CEO Z phát biểu tại hội nghị X" — trừ khi công bố roadmap
A25: Tech review consumer gadget | B25: "iPhone 18 review", "Samsung Galaxy S26 unboxing" — trừ khi feature ảnh hưởng super-app
A26: Entertainment/ Spports | B26: Tin giải trí/thể thao không có góc platform/tech

Sheet Grading
A1: Bảng tính điểm
A2: Score | B2: Level
A3: 4.21 – 5.00 | B3: 5 – Industry disruption
A4: 3.41 – 4.20 | B4: 4 – Strategic shift
A5: 2.51 – 3.40 | B5: 3 – Market signal
A6: 1.61 – 2.50 | B6: 2 – Minor signal
A7: ≤ 1.60 | B7: 1 – Noise
A9: Công thức tính
A10: signal_score = D1 × 0.6 + D2 × 0.4
A12: R1 - Impact | B12: 0.6 | C12: TA có thể action được gì từ tin này không? | E12: R2 - Relevance | F12: 0.4 | G12: Tin này có thuộc liên quan đến các vertical không
A13: Score | B13: 5 | C13: Regulation đã ban hành áp lên vertical TA đang vận hành Đối thủ trực tiếp launch product/pricing change đụng vertical TA Infrastructure/tool TA đang dùng có breaking change | E13: Score | F13: 5 | G13: Liên quan 2+ vertical core + content actionable
B14: 4 | C14: Đối thủ peer launch feature mới (chưa cùng vertical TA, có pattern apply) Tool / infrastructure mới TA có thể adopt (Stripe Link, Ant AMP...) Banking/fintech entry tạo lựa chọn mới Regulation precedent ở SEA/TQ — sắp đến VN | F14: 4 | G14: Liên quan đến 1+ vertical core + cotent actionable
B15: 3 | C15: AI tech advance không trực tiếp super-app (DeepSeek V4, GPT update) Corporate news ngành (CEO turnover, earnings có nuance) Routine player promo / feature minor (Grab promo tuần) Regulation distant / proposed-not-enacted | F15: 3 | G15: Adjacent: banking partner, regulatory precedent, 1 vertical thin / cross-vertical signal
B16: 2 | C16: Niche partnership cho use case nhỏ (kiều hối routine) Vertical mới chưa scale (insurance digital VN) Trend gián tiếp | F16: 2 | G16: Background signal — xu hướng gián tiếp, chưa có actor cụ thể
B17: 1 | C17: Dev tooling thuần (OpenAI Agents SDK) HR/AI hype không product implication B2G/B2D không tạo precedent | F17: 1 | G17: Hoàn toàn ngoài HST scope
A18: Modifiers cho D1 | B18: Market Pulse | C18: TQ event với precedent rõ cho VN → cộng 0.3–0.5 Quốc tế (US/EU) chỉ là "tin tham khảo" → giảm 0.3–0.5
B19: Market Pulse | C19: Tin đồn/leak chưa confirm → cap D1 ≤ 3 B2B/enterprise solutions (dù có AI) → cap D1 ≤ 2
B20: Players Movement | C20: Promo định kỳ → cap D1 ≤ 3.5 Product launch/Pricing/M&A/ Feature update → D1 ≥ 4

Sheet Updating-Scoring
A1: Impact score framework
A2: Score | B2: Range | C2: Min | D2: Meaning | E2: Mô tả
A3: 1 | B3: 1-1.8 | C3: 1 | D3: 1 - Noise | E3: Định nghĩa: Tin viral hoặc thú vị nhưng không có giá trị chiến lược. Không tạo ra insight gì về thị trường. Tiêu chí nhận diện: - Câu chuyện consumer/viral không phản ánh xu hướng thị trường - Sản phẩm/feature niche, không có relevance với VN/SEA - Nội dung hành chính/thủ tục không ảnh hưởng đến doanh nghiệp tư nhân - Ví dụ: MacBook warranty hack viral; Ứng dụng kết bạn tại Mỹ; HanoiWork OKR/KPI; United Airlines TSA wait times; Beehiiv mở rộng sang podcast
A4: 2 | B4: 1.81 - 3.0 | C4: 1.81 | D4: 2 - Minor signal | E4: Định nghĩa: Tin tức liên quan, cung cấp context hữu ích nhưng không tạo áp lực thay đổi gì. Người đọc có thể bỏ qua mà không ảnh hưởng đến quyết định. Tiêu chí nhận diện: - Product update, feature launch không thay đổi competitive landscape - Số liệu tham khảo từ thị trường khác, liên quan gián tiếp - Regulatory/legal ở giai đoạn dự thảo hoặc thị trường ngoài - Ví dụ: ElevenLabs AI music app; Rakuten rebrand DeepSeek V3; CMC đặt mục tiêu 20%; VNEID traffic reporting feature; Facebook Messenger web đóng
A5: 3 | B5: 3.01 - 3.4 | C5: 3.01 | D5: 3 - Market signal | E5: Định nghĩa: Tín hiệu đáng theo dõi, phản ánh xu hướng hoặc sự kiện có tác động đến thị trường nhưng chưa tạo ra hành động ngay. Người đọc cần biết để chuẩn bị, không cần phản ứng ngay. Tiêu chí nhận diện: - Dữ liệu thị trường quan trọng nhưng chưa là bước ngoặt - Nghiên cứu/báo cáo cung cấp insight mới về hành vi user hoặc ngành - Sự kiện tạo precedent quan trọng (pháp lý, kỹ thuật, chính sách) - Ví dụ: MIT AI confirmation bias research; 82% Indonesia AI shopping; DeepSeek outage 7h; Cuộc đua AI video sau Sora; Bitget crypto Visa APAC; Luật SHTT sửa đổi
A6: 4 | B6: 3.41-4.20 | C6: 3.41 | D6: 4 - Strategic shift | E6: Định nghĩa: Hành động cụ thể của một player có trọng lượng, buộc các đối thủ hoặc ngành phải phản ứng. Phân biệt với 5: tác động chưa thay đổi toàn bộ cấu trúc, nhưng đã rõ ràng và cụ thể. Tiêu chí nhận diện: - Một công ty lớn thực hiện bước đi chiến lược rõ ràng (launch, partnership cụ thể, M&A) - Quy định/pháp lý tạo ra hành động bắt buộc ngay (không phải định hướng xa) - Tác động cạnh tranh rõ ràng lên ít nhất một nhóm player - Ví dụ: Shinsegae hợp tác OpenAI AI Commerce; Meta thử nghiệm Instagram Plus; Google AI viết lại SERP title; AI tấn công 1M+ doanh nghiệp Việt; Bộ KH&CN xây danh mục AI rủi ro cao
A7: 5 | B7: 4.21 - 5.0 | C7: 4.21 | D7: 5 - Industry disruption | E7: Định nghĩa: Thay đổi căn bản cách một ngành/thị trường vận hành tại VN/SEA. Không phải tin lớn toàn cầu – phải là structural change ảnh hưởng trực tiếp đến người dùng hoặc doanh nghiệp trong nước. Tiêu chí nhận diện: - Cấu trúc thị trường VN/SEA thay đổi (ai thắng/thua thị phần, ngành mới hình thành) - Buộc nhiều player phải thay đổi mô hình kinh doanh đồng thời - Dữ liệu/số liệu thể hiện bước ngoặt thực sự (không chỉ tăng trưởng thông thường) - Ví dụ: TikTok Shop/Shopee chiếm 70%+ beauty TMĐT VN; TMĐT +34% nhưng toàn ngành không có lãi; Alibaba AI agents cho hàng triệu merchant; MobiFone vào hạ tầng thanh toán lõi
A9: Impact score decision table
B10: Criteria | C10: Low | D10: Medium | E10: High
B11: Market Scope | C11: company | D11: country | E11: global
B12: Industry Impact | C12: niche | D12: sector | E12: multi-sector
B13: Time Horizon | C13: short-term | D13: medium | E13: structural
B14: Strategic Relevance | C14: tactical | D14: strategic | E14: paradigm shift
A16: Impact scoring logic
B17: Impact score = average (market_scope, industry_impact, time_horizon, strategic_revlevance)
A19: Rule chọn tin bài phù hợp/ liên quan
A20: No | B20: Rule | C20: Weight | D20: Details | E20: Description
A21: Rule 1 | B21: Strategic relevance | C21: 0.4 | D21: - Fintech - payment/ wallet - Technology - AI/ chatbot - Platform ecosystem - Superapp - Regulation - Fintech / AI - Digital infrastructure - Indentiy/ Payment rails | E21: Mức độ tác động trực tiếp đến cách doanh nghiệp cạnh tranh trong thị trường VN/SEA. Không phải tầm quan trọng toàn cầu hay chính sách vĩ mô. - 5: Thay đổi cấu trúc cạnh tranh ngay lập tức tại VN/SEA (ai thắng/thua thị phần) - 4: Buộc player trong ngành phải điều chỉnh chiến lược - 3: Ảnh hưởng đến 1-2 mảng kinh doanh cụ thể - 2: Tín hiệu chiến lược nhưng chưa rõ tác động - 1: Không liên quan đến VN/SEA market
A22: Rule 2 | B22: Market impact | C22: 0.25 | D22: - Ảnh hưởng đến ngành - Ảnh hưởng đến nhiều công ty - Ảnh hưởng đến pháp lý - Ảnh hưởng đến hạ tầng nền tảng | E22: Quy mô người dùng/merchant/doanh nghiệp thực sự bị ảnh hưởng. Tính theo breadth (bao nhiêu người) × depth (ảnh hưởng sâu đến đâu). - 5: Ảnh hưởng toàn bộ thị trường (triệu users hoặc toàn ngành) - 4: Ảnh hưởng phân khúc lớn hoặc nhiều ngành - 3: Ảnh hưởng một nhóm rõ ràng (e.g. merchant, fintech startup) - 2: Ảnh hưởng hẹp hoặc gián tiếp - 1: Tác động không đáng kể
A23: Rule 3 | B23: Competitive intelligence | C23: 0.2 | D23: - Momo - Zalopay - BigTech | E23: Mức độ thay đổi thế cạnh tranh giữa các player, bao gồm cả competitive threat với doanh nghiệp trong nước. Tính theo: ai được lợi, ai bị đe dọa. - 5: Một player giành hoặc mất lợi thế cạnh tranh lớn ngay lập tức - 4: Tạo áp lực cạnh tranh rõ ràng lên các đối thủ hiện tại - 3: Mở ra hoặc đóng cửa một mảng cạnh tranh - 2: Tín hiệu cạnh tranh nhưng chưa có hành động cụ thể - 1: Không ảnh hưởng đến landscape cạnh tranh
A24: Rule 4 | B24: Technology inflection | C24: 0.15 | D24: - AI infrastructure - AI superapp - AI productization | E24: Mức độ công nghệ kích hoạt hành vi mới hoặc làm lỗi thời cách làm cũ. Không chỉ là innovation thuần kỹ thuật — behavioral shift, platform shift, và infrastructure shift đều tính. - 5: Tạo ra category mới hoặc làm lỗi thời một cách làm cũ hoàn toàn - 4: Shift rõ ràng trong cách user/business tương tác với technology - 3: Nâng cấp đáng kể khả năng hiện tại - 2: Cải tiến incremental, không thay đổi cơ bản - 1: Không có tech inflection
A26: Phân tích logic lọc bài của bạn
A28: 1. Tiêu chí nguồn (Source tier)
A30: Tier | B30: Nguồn | C30: Vai trò
A31: Domestic tech | B31: GenK, VNExpress, Dân Trí, VNEconomy TechConnect | C31: Thị trường VN
A32: Regulatory | B32: Luật Việt Nam | C32: Compliance/chính sách
A33: Regional | B33: TechInAsia | C33: SEA context
A34: Global | B34: TechCrunch, Bloomberg | C34: Xu hướng quốc tế
A36: → Logic: Bao phủ đa tầng — VN nội địa + SEA + Global, không lọc theo nguồn mà lọc theo nội dung.
A40: 2. Tiêu chí chủ đề (Topic relevance)
A42: Nhìn vào các bài được qualified, có thể thấy 5 nhóm chủ đề được chấp nhận:
A44: Nhóm | B44: Ví dụ trong list | C44: Liên quan super-app
A45: AI tools & platform | B45: OpenClaw, ChatGPT, Gemini, OpenAI superapp | C45: V-AI, cạnh tranh assistant
A46: Mobile/app ecosystem | B46: iOS 27, Apple Dev metrics, WhatsApp AI | C46: App development context
A47: Payments & fintech | B47: TT30/NHNN, FOMO Pay AI soundbox, Indonesia QR | C47: VPoint, thanh toán
A48: Platform & e-commerce | B48: Meta shopping AI, TikTok ads, Shopee/TikTok couriers | C48: Ecosystem cạnh tranh
A49: Vietnam regulations | B49: Smartphone safety, AI governance law, TT18 hộ KD | C49: Compliance
A52: 3. Tiêu chí loại trừ (Disqualified)
A54: Các bài không có trong list của bạn thường rơi vào:
A56: Tin tài chính/đầu tư thuần túy (stocks, earnings không liên quan platform)
...

Sheet Coding
A1: Bước 1: Lựa chọn source | K1: Strategy | L1: Product | M1: Feature | N1: Partnerhsip | O1: User activation | P1: User engagement | Q1: User acquisition | R1: Transaction growth
A2: Source
A3: code | B3: source_name
A4: 1 | B4: GenK
A5: 2 | B5: Báo tin tức
A6: 3 | B6: VNEconomy
A7: 4 | B7: Dân Trí
A8: 5 | B8: VNExpress
A9: 6 | B9: Thư viện pháp luật
A10: 7 | B10: Luật Việt Nam
A11: 8 | B11: ZaloPay website
A12: 9 | B12: ZaloPay fanpage
A13: 10 | B13: MoMo wesbite
A14: 11 | B14: MoMo fanpage
A16: Nguyên tắc phân loại Bước 2 - Bài viết là hành động chủ động của 1 players thuộc list bên dưới và hiệu lực/ được áp dụng tại Việt Nam: Players Movement - Bài viết còn lại (tin thị trường, regulation, peer global, players): Market Pulse - Sub_topic_group trong Market Pulse là phạm vi của sự kiện trong bài viết xảy ra - Sub_topic_group trong Players Movement tách riêng Zalo, ZaloPay: + Action/Event liên quan thanh toán, payment, QR, ví điện tử, kiều hối, BNPL → ZaloPay + Action/Event liên quan chat, mini app, social, OA, AI assistant trong Zalo → Zalo
A17: Bước 2: Phân loại theo topic_group
A18: Topic Group
A19: no_1 | B19: topic_group | C19: no_2 | D19: sub_topic_group | E19: no_final | F19: topic_aggregrate
A20: 1 | B20: Market Pulse | C20: =COUNTIF($B$20:B20,B20) -> 1 | D20: Quốc tế | E20: =_xlfn.TEXTJOIN(".",TRUE,A20,C20) -> 1.1 | F20: =_xlfn.TEXTJOIN(" | ",TRUE,B20,D20) -> Market Pulse | Quốc tế
A21: 1 | B21: Market Pulse | C21: =COUNTIF($B$20:B21,B21) -> 2 | D21: Trung quốc | E21: =_xlfn.TEXTJOIN(".",TRUE,A21,C21) -> 1.2 | F21: =_xlfn.TEXTJOIN(" | ",TRUE,B21,D21) -> Market Pulse | Trung quốc
A22: 1 | B22: Market Pulse | C22: =COUNTIF($B$20:B22,B22) -> 3 | D22: SEA | E22: =_xlfn.TEXTJOIN(".",TRUE,A22,C22) -> 1.3 | F22: =_xlfn.TEXTJOIN(" | ",TRUE,B22,D22) -> Market Pulse | SEA
A23: 1 | B23: Market Pulse | C23: =COUNTIF($B$20:B23,B23) -> 4 | D23: Trong nước | E23: =_xlfn.TEXTJOIN(".",TRUE,A23,C23) -> 1.4 | F23: =_xlfn.TEXTJOIN(" | ",TRUE,B23,D23) -> Market Pulse | Trong nước
A24: 2 | B24: Players Movement | C24: =COUNTIF($B$20:B24,B24) -> 1 | D24: MoMo | E24: =_xlfn.TEXTJOIN(".",TRUE,A24,C24) -> 2.1 | F24: =_xlfn.TEXTJOIN(" | ",TRUE,B24,D24) -> Players Movement | MoMo
A25: 2 | B25: Players Movement | C25: =COUNTIF($B$20:B25,B25) -> 2 | D25: Zalo | E25: =_xlfn.TEXTJOIN(".",TRUE,A25,C25) -> 2.2 | F25: =_xlfn.TEXTJOIN(" | ",TRUE,B25,D25) -> Players Movement | Zalo
A26: 2 | B26: Players Movement | C26: =COUNTIF($B$20:B26,B26) -> 3 | D26: Zalopay | E26: =_xlfn.TEXTJOIN(".",TRUE,A26,C26) -> 2.3 | F26: =_xlfn.TEXTJOIN(" | ",TRUE,B26,D26) -> Players Movement | Zalopay
A27: 2 | B27: Players Movement | C27: =COUNTIF($B$20:B27,B27) -> 4 | D27: Traveloka | E27: =_xlfn.TEXTJOIN(".",TRUE,A27,C27) -> 2.4 | F27: =_xlfn.TEXTJOIN(" | ",TRUE,B27,D27) -> Players Movement | Traveloka
A28: 2 | B28: Players Movement | C28: =COUNTIF($B$20:B28,B28) -> 5 | D28: WhatsApp | E28: =_xlfn.TEXTJOIN(".",TRUE,A28,C28) -> 2.5 | F28: =_xlfn.TEXTJOIN(" | ",TRUE,B28,D28) -> Players Movement | WhatsApp
A29: 2 | B29: Players Movement | C29: =COUNTIF($B$20:B29,B29) -> 6 | D29: Telegram | E29: =_xlfn.TEXTJOIN(".",TRUE,A29,C29) -> 2.6 | F29: =_xlfn.TEXTJOIN(" | ",TRUE,B29,D29) -> Players Movement | Telegram
A30: 2 | B30: Players Movement | C30: =COUNTIF($B$20:B30,B30) -> 7 | D30: Shopee | E30: =_xlfn.TEXTJOIN(".",TRUE,A30,C30) -> 2.7 | F30: =_xlfn.TEXTJOIN(" | ",TRUE,B30,D30) -> Players Movement | Shopee
A31: 2 | B31: Players Movement | C31: =COUNTIF($B$20:B31,B31) -> 8 | D31: TiktokShop | E31: =_xlfn.TEXTJOIN(".",TRUE,A31,C31) -> 2.8 | F31: =_xlfn.TEXTJOIN(" | ",TRUE,B31,D31) -> Players Movement | TiktokShop
A32: 2 | B32: Players Movement | C32: =COUNTIF($B$20:B32,B32) -> 9 | D32: Grab | E32: =_xlfn.TEXTJOIN(".",TRUE,A32,C32) -> 2.9 | F32: =_xlfn.TEXTJOIN(" | ",TRUE,B32,D32) -> Players Movement | Grab
A34: Nguyên tắc phân loại Bước 3 - Phân biệt Product vs Feature: Product là "1 sản phẩm mới có thể đứng độc lập" (Ví Trả Sau, Gói Thành Viên). Feature là "thêm chức năng trong sản phẩm có sẵn" (chuyển khoản nhanh, OTP mới, UX redesign) - Phân biệt Marketing vs Strategy: Marketing là campaign có thời hạn (voucher, mã giảm, livestream tuần). Strategy là tuyên bố/lộ trình dài hạn (mở rộng quốc gia, mua lại startup, AI roadmap)
A35: Bước 3: Phân loại content theo category_group
A36: Category Group
A37: no_1 | B37: topic_group | C37: no_3 | D37: category_group | E37: definition
A38: 1 | B38: Market Pulse | C38: =COUNTIF($B$38:B38,B38) -> 1 | D38: Political | E38: Chính sách, sắc lệnh, chiến lược quốc gia, geopolitics
A39: 1 | B39: Market Pulse | C39: =COUNTIF($B$38:B39,B39) -> 2 | D39: Economic | E39: Funding, M&A, mở rộng thị trường, đổi mô hình kinh doanh, sáng kiến chính phủ về kinh tế
A40: 1 | B40: Market Pulse | C40: =COUNTIF($B$38:B40,B40) -> 3 | D40: Social | E40: Hành vi người dùng, thói quen thanh toán số, chấp nhận AI,…
A41: 1 | B41: Market Pulse | C41: =COUNTIF($B$38:B41,B41) -> 4 | D41: Technology | E41: AI, blockchain, open banking, cloud, cybersecurity, platform policy
A42: 1 | B42: Market Pulse | C42: =COUNTIF($B$38:B42,B42) -> 5 | D42: Legal | E42: Luật, Thông tư, Nghị định, Quyết định
...

Sheet Database
A1: Auto | B1: Fill | D1: Drop_down list | E1: Auto | F1: Auto | G1: Fill | H1: Fill | I1: Fill | J1: Drop_down list | K1: Drop_down list | L1: Drop_down list | M1: Drop_down list | O1: Fill | P1: Fill | Q1: Fill | R1: Fill | S1: Fill | T1: 0.4 | U1: 0.25 | V1: 0.2 | W1: 0.15 | X1: Calculation
T2: 0.6 | U2: 0.4
A3: id | B3: url | C3: hyperlink | D3: source_name | E3: signal_level | F3: week | G3: crawl_date | H3: title_raw | I3: publish_date | J3: topic_group | K3: sub_topic_group | L3: category | M3: subcategory | N3: merged_category | O3: title_normalized | P3: summary | Q3: start_date | R3: end_date | S3: tags | T3: R1 | U3: R2 | V3: R3 | W3: R4 | X3: signal_score | Y3: related _vertical | Z3: related_product_2
A4: =ROW()-3 -> 1 | B4: https://thuvienphapluat.vn/van-ban/Tien-te-Ngan-hang/Thong-tu-77-2025-TT-NHNN-sua-doi-Thong-tu-50-2024-TT-NHNN-688630.aspx | C4: =HYPERLINK(B4,O4) -> Thông tư 77/2025/TT-NHNN ngày 31/12/2025 có hiệu lực từ 1/3/2026 | D4: Thư viện pháp luật | E4: =VLOOKUP(X4,'Updating-Scoring'!$C$2:$D$7,2,TRUE) -> 5 - Industry disruption | F4: =WEEKNUM(G4,2) -> 9 | G4: 46082 | H4: Ứng dụng Mobile Banking sẽ tự thoát khi điện thoại không bảo mật từ 01/3/2026 | I4: 46022 | J4: Market Pulse | K4: Trong nước | L4: Legal | M4: Banking / Fintech | N4: =L4&" | "&M4 -> Legal | Banking / Fintech | O4: Thông tư 77/2025/TT-NHNN ngày 31/12/2025 có hiệu lực từ 1/3/2026 | P4: Thông tư bổ sung nhiều yêu cầu mới về an toàn, bảo mật ứng dụng Mobile Banking, từ kiểm soát phiên bản phần mềm đến phòng chống tấn công mạng và gian lận bằng công nghệ cao. Ứng dụng Mobile Banking phải tự động thoát hoặc dừng hoạt động và thông báo cho khách hàng lý do nếu phát hiện các dấu hiệu mất an toàn Các giải pháp phát hiện giả mạo sinh trắc học phải đạt chuẩn quốc tế ISO 30107 cấp độ 2 Siết chặt quản lý phiên bản ứng dụng Mobile Banking. Theo quy định mới, tối thiểu 3 tháng một lần, các tổ chức tín dụng phải tổ chức đánh giá mức độ an toàn, bảo mật đối với các phiên bản ứng dụng đang được phép cài đặt, sử dụng, qua đó kịp thời phát hiện lỗ hổng và nguy cơ bị tội phạm mạng can thiệp | Q4: 46082 | S4: Luật; Thông tư; NHNN; Mobile Banking | T4: 5 | U4: 5 | V4: 5 | W4: 5 | X4: =IF(G4<DATE(2026,4,30),T4*$T$1+U4*$U$1+V4*$V$1+W4*$W$1,T4*$T$2+U4*$U$2) -> 5
A5: =ROW()-3 -> 2 | B5: https://thuvienphapluat.vn/van-ban/Cong-nghe-thong-tin/Luat-Tri-tue-nhan-tao-2025-so-134-2025-QH15-679013.aspx | C5: =HYPERLINK(B5,O5) -> Luật Trí tuệ nhân tạo số 134/2025/QH15 do Quốc hội ban hành chính thức áp dụng từ 1/3/2026 | D5: Thư viện pháp luật | E5: =VLOOKUP(X5,'Updating-Scoring'!$C$2:$D$7,2,TRUE) -> 5 - Industry disruption | F5: =WEEKNUM(G5,2) -> 9 | G5: 46082 | H5: Luật Trí tuệ nhân tạo 2025 số 134/2025/QH15 áp dụng năm 2026 | I5: 45942 | J5: Market Pulse | K5: Trong nước | L5: Legal | M5: AI | N5: =L5&" | "&M5 -> Legal | AI | O5: Luật Trí tuệ nhân tạo số 134/2025/QH15 do Quốc hội ban hành chính thức áp dụng từ 1/3/2026 | P5: Các hệ thống AI tương tác trực tiếp với con người phải được thiết kế để người dùng biết mình đang làm việc với máy. Đồng thời, nội dung dạng âm thanh, hình ảnh hoặc video do AI tạo ra phải được đánh dấu bằng dấu hiệu nhận biết theo quy định của Chính phủ Phân loại và quản trị hệ thống trí tuệ nhân tạo theo rủi ro để áp dụng biện pháp phù hợp, khuyến khích đổi mới nhưng ưu tiên bảo vệ quyền lợi người bị ảnh hưởng | Q5: 46082 | S5: Luật; Trí tuệ nhân tạo | T5: 5 | U5: 5 | V5: 5 | W5: 5 | X5: =IF(G5<DATE(2026,4,30),T5*$T$1+U5*$U$1+V5*$V$1+W5*$W$1,T5*$T$2+U5*$U$2) -> 5
A6: =ROW()-3 -> 3 | B6: https://genk.vn/chi-dao-moi-nghien-cuu-tich-hop-mang-xa-hoi-vao-vneid-de-dinh-danh-nguoi-dung-ngay-trong-nam-2026-165260222142344609.chn | C6: =HYPERLINK(B6,O6) -> Nghiên cứu tích hợp mạng xã hội vào VNeID để định danh người dùng ngay trong Quý III/2026 | D6: GenK | E6: =VLOOKUP(X6,'Updating-Scoring'!$C$2:$D$7,2,TRUE) -> 5 - Industry disruption | F6: =WEEKNUM(G6,2) -> 9 | G6: 46082 | H6: Chỉ đạo mới: Nghiên cứu tích hợp mạng xã hội vào VNeID để định danh người dùng ngay trong năm 2026 | I6: 46075 | J6: Market Pulse | K6: Trong nước | L6: Political | M6: Natinal digital strategy | N6: =L6&" | "&M6 -> Political | Natinal digital strategy | O6: Nghiên cứu tích hợp mạng xã hội vào VNeID để định danh người dùng ngay trong Quý III/2026 | P6: Theo chương trình công tác năm 2026, Ban Chỉ đạo Trung ương về phát triển khoa học, công nghệ, đổi mới sáng tạo và chuyển đổi số giao Chính phủ rà soát, nghiên cứu giải pháp kỹ thuật liên kết, tích hợp các dịch vụ mạng xã hội với hệ thống VNeID Việc tích hợp nhằm phục vụ xác thực và định danh người dùng trên không gian mạng, bảo đảm tuân thủ quy định pháp luật trong nước cũng như các cam kết quốc tế mà Việt Nam tham gia Theo kế hoạch, nhiệm vụ này cần hoàn tất trong quý III năm nay. | Q6: 46081 | R6: 46296 | S6: VNeID; tích hợp; mạng xã hội | T6: 5 | U6: 5 | V6: 5 | W6: 5 | X6: =IF(G6<DATE(2026,4,30),T6*$T$1+U6*$U$1+V6*$V$1+W6*$W$1,T6*$T$2+U6*$U$2) -> 5
A7: =ROW()-3 -> 4 | B7: https://baotintuc.vn/thi-truong-tien-te/doanh-nghiep-tang-toc-chuan-bi-cho-thi-diem-san-giao-dich-tai-san-ma-hoa-20260226191937609.htm | C7: =HYPERLINK(B7,O7) -> Thị trường giao dịch tài sản mã hóa sẽ được đưa vào vận hành thí điểm trước ngày 28/2/2026 | D7: Báo tin tức | E7: =VLOOKUP(X7,'Updating-Scoring'!$C$2:$D$7,2,TRUE) -> 5 - Industry disruption | F7: =WEEKNUM(G7,2) -> 9 | G7: 46082 | H7: Doanh nghiệp tăng tốc chuẩn bị cho thí điểm sàn giao dịch tài sản mã hóa | I7: 46079 | J7: Market Pulse | K7: Trong nước | L7: Legal | M7: Digital money | N7: =L7&" | "&M7 -> Legal | Digital money | O7: Thị trường giao dịch tài sản mã hóa sẽ được đưa vào vận hành thí điểm trước ngày 28/2/2026 | P7: Các doanh nghiệp Việt Nam đang đẩy nhanh chuẩn bị, tăng vốn và hoàn thiện hệ thống để tham gia thí điểm sàn giao dịch tài sản mã hóa. CAEX và các công ty khác tập trung vào an toàn, bảo mật, quản trị rủi ro theo chuẩn quốc tế, trong bối cảnh khung pháp lý đang hoàn thiện với yêu cầu vốn điều lệ tối thiểu và cơ cấu cổ đông phù hợp | Q7: 46023 | R7: 46080 | S7: Kinh tế; Vận hành thí điểm; Sàn giao dịch; Tiền mã khóa | T7: 5 | U7: 5 | V7: 5 | W7: 5 | X7: =IF(G7<DATE(2026,4,30),T7*$T$1+U7*$U$1+V7*$V$1+W7*$W$1,T7*$T$2+U7*$U$2) -> 5
A8: =ROW()-3 -> 5 | B8: https://baomoi.com/google-ra-mat-nano-banana-2-cai-tien-toc-do-va-kha-nang-tao-anh-ai-chat-luong-4k-c54567264.epi | C8: =HYPERLINK(B8,O8) -> Google ra mắt mô hình tạo ảnh mới Nano Banana 2, tham vọng phủ sóng toàn hệ sinh thái AI | D8: Báo mới | E8: =VLOOKUP(X8,'Updating-Scoring'!$C$2:$D$7,2,TRUE) -> 5 - Industry disruption | F8: =WEEKNUM(G8,2) -> 9 | G8: 46082 | H8: Google ra mắt mô hình tạo ảnh mới Nano Banana 2, tham vọng phủ sóng toàn hệ sinh thái AI | I8: 46080 | J8: Market Pulse | K8: Quốc tế | L8: Technology | M8: AI/ Gen AI | N8: =L8&" | "&M8 -> Technology | AI/ Gen AI | O8: Google ra mắt mô hình tạo ảnh mới Nano Banana 2, tham vọng phủ sóng toàn hệ sinh thái AI | P8: Nano Banana 2 có tên chính thức là Gemini 3.1 Flash Image. Theo Google, mô hình này kết hợp khả năng suy luận chuyên sâu của biến thể Pro trước đó với độ phản hồi nhanh của Gemini Flash. Hệ thống được cho là có thể khai thác kiến thức thực tế và tham chiếu thông tin web cập nhật để tái hiện chính xác các chủ thể cụ thể. Nhờ đó, người dùng có thể tạo ra infographic chi tiết, sơ đồ có cấu trúc rõ ràng và các hình ảnh dựa trên dữ liệu với độ chính xác ngữ cảnh được cải thiện | S8: AI; Google; Nano Banana 2; Gemini Flash | T8: 5 | U8: 5 | V8: 5 | W8: 5 | X8: =IF(G8<DATE(2026,4,30),T8*$T$1+U8*$U$1+V8*$V$1+W8*$W$1,T8*$T$2+U8*$U$2) -> 5
A9: =ROW()-3 -> 6 | B9: https://baomoi.com/5-xu-huong-ai-se-dinh-hinh-chien-luoc-lanh-dao-nam-2026-c54541582.epi | C9: =HYPERLINK(B9,O9) -> Sự tăng tốc của các hệ sinh thái super-app “AI-FIRST” | D9: Báo mới | E9: =VLOOKUP(X9,'Updating-Scoring'!$C$2:$D$7,2,TRUE) -> 5 - Industry disruption | F9: =WEEKNUM(G9,2) -> 9 | G9: 46082 | H9: 5 xu hướng AI sẽ định hình chiến lược lãnh đạo năm 2026 | I9: 46077 | J9: Market Pulse | K9: Quốc tế | L9: Technology | M9: AI/ Gen AI | N9: =L9&" | "&M9 -> Technology | AI/ Gen AI | O9: Sự tăng tốc của các hệ sinh thái super-app “AI-FIRST” | P9: AI đang chuyển từ vai trò “công cụ hỗ trợ” sang trở thành một tầng vận hành chiến lược của doanh nghiệp, nơi các tác nhân AI (agentic AI) có khả năng tự lập kế hoạch, điều phối quy trình và thay đổi cấu trúc lãnh đạo truyền thống. Năm 2026, các super-app AI‑first và hệ sinh thái AI bản địa hóa sẽ trở thành lợi thế cạnh tranh cốt lõi, buộc lãnh đạo doanh nghiệp phải tái thiết kế lực lượng lao động, mô hình tổ chức và phương thức ra quyết định. | S9: AI; Tác nhân AI; Agent; Xu hướng | T9: 5 | U9: 5 | V9: 5 | W9: 5 | X9: =IF(G9<DATE(2026,4,30),T9*$T$1+U9*$U$1+V9*$V$1+W9*$W$1,T9*$T$2+U9*$U$2) -> 5
A10: =ROW()-3 -> 7 | B10: https://vneconomy.vn/techconnect/cac-ong-lon-cong-nghe-trung-quoc-chay-dua-xay-dung-sieu-ung-dung-ai.htm | C10: =HYPERLINK(B10,O10) -> Alibaba, Baidu, ByteDance và Tencent đang chạy đua biến chatbot thành công cụ mua sắm | D10: VNEconomy | E10: =VLOOKUP(X10,'Updating-Scoring'!$C$2:$D$7,2,TRUE) -> 5 - Industry disruption | F10: =WEEKNUM(G10,2) -> 9 | G10: 46082 | H10: Các “ông lớn” công nghệ Trung Quốc chạy đua xây dựng siêu ứng dụng AI | I10: 46045 | J10: Market Pulse | K10: Trung quốc | L10: Technology | M10: AI/ Gen AI | N10: =L10&" | "&M10 -> Technology | AI/ Gen AI | O10: Alibaba, Baidu, ByteDance và Tencent đang chạy đua biến chatbot thành công cụ mua sắm | P10: Alibaba đã nâng cấp chatbot AI Qwen 3.5, cho phép người dùng hoàn tất giao dịch trực tiếp trong giao diện trò chuyện. Thông qua bản cập nhật này, người dùng có thể đặt đồ ăn, mua vé máy bay, so sánh sản phẩm, đặt phòng khách sạn và thanh toán – tất cả mà không cần rời khỏi chatbot Điểm khác biệt lớn nhất của Qwen phiên bản mới nằm ở khả năng kết nối sâu với toàn bộ hệ sinh thái thương mại của Alibaba. AI có thể truy xuất dữ liệu và đề xuất sản phẩm từ Taobao, Tmall, Fliggy (du lịch), các dịch vụ giao đồ ăn, rồi xử lý thanh toán qua Alipay Đầu tháng 2, chiến dịch tặng phiếu giảm giá khi đặt trà sữa qua AI Qwen của Alibaba với ngân sách 3 tỷ NDT đã giúp lượng người dùng hoạt động của Qwen tăng gấp 7 lần. Trước đó, Tencent khởi động chương trình phát lì xì trị giá 1 tỷ NDT (khoảng 140 triệu USD) thông qua trợ lý AI Yuanbao. Không lâu sau, Baidu tung ra gói 500 triệu NDT cho Wenxin (Wechat) AI | S10: AI; Agentic commerce; chatbot AI; Thương mại điện tử; Trung Quốc; AI Agent | T10: 5 | U10: 5 | V10: 5 | W10: 5 | X10: =IF(G10<DATE(2026,4,30),T10*$T$1+U10*$U$1+V10*$V$1+W10*$W$1,T10*$T$2+U10*$U$2) -> 5
A11: =ROW()-3 -> 8 | B11: https://genk.vn/galaxy-s26-series-co-7-tinh-nang-ai-moi-tu-mo-app-goi-xe-dat-do-an-chinh-anh-bang-loi-noi-tu-nghe-cuoc-goi-nguoi-la-16526022601523337.chn | C11: =HYPERLINK(B11,O11) -> Galaxy S26 series sẽ mang đến 7 nâng cấp AI mới, tập trung vào tự động hóa tác vụ đa bước,..triển khai trước tại Mỹ và Hàn Quốc | D11: GenK | E11: =VLOOKUP(X11,'Updating-Scoring'!$C$2:$D$7,2,TRUE) -> 5 - Industry disruption | F11: =WEEKNUM(G11,2) -> 9 | G11: 46082 | H11: Galaxy S26 series có 7 tính năng AI mới: Tự mở app gọi xe, đặt đồ ăn, chỉnh ảnh bằng lời nói, tự nghe cuộc gọi người lạ… | I11: 46079 | J11: Market Pulse | K11: Quốc tế | L11: Technology | M11: AI/ Gen AI | N11: =L11&" | "&M11 -> Technology | AI/ Gen AI | O11: Galaxy S26 series sẽ mang đến 7 nâng cấp AI mới, tập trung vào tự động hóa tác vụ đa bước,..triển khai trước tại Mỹ và Hàn Quốc | P11: Gemini được nâng cấp vượt khỏi mô hình chatbot truyền thống, trợ lý Agentic AI này có thể trực tiếp thao tác ứng dụng thay cho người dùng và xử lý các tác vụ nhiều bước vốn trước đây yêu cầu chuyển qua lại giữa 3 đến 4 app. Ở giai đoạn beta, tính năng này được triển khai trước tại Mỹ và Hàn Quốc. 3 nhóm tác vụ chính được hỗ trợ gồm đặt lại món quen trên DoorDash hoặc Uber Eats, so sánh và đặt xe giữa các nền tảng hỗ trợ, xây dựng giỏ hàng tạp hóa từ công thức nấu ăn hoặc lịch sử mua sắm thông qua các đối tác như Kroger và Walmart. Theo thông tin hiện tại, phiên bản Gemini agentic này chỉ có trên dòng Galaxy S26 và Pixel 10 | S11: AI; Galaxy AI | T11: 5 | U11: 5 | V11: 5 | W11: 5 | X11: =IF(G11<DATE(2026,4,30),T11*$T$1+U11*$U$1+V11*$V$1+W11*$W$1,T11*$T$2+U11*$U$2) -> 5
A12: =ROW()-3 -> 9 | B12: https://zalopay.vn/thong-bao-zalopay-nang-cap-bao-mat-theo-thong-tu-77-8302 | C12: =HYPERLINK(B12,O12) -> Zalopay nâng cấp bảo mật theo Thông tư 77/2025/TT-NHNN, tăng cường an toàn giao dịch cho người dùng | D12: ZaloPay Wesbite | E12: =VLOOKUP(X12,'Updating-Scoring'!$C$2:$D$7,2,TRUE) -> 5 - Industry disruption | F12: =WEEKNUM(G12,2) -> 9 | G12: 46082 | H12: Zalopay nâng cấp bảo mật theo Thông tư 77/2025/TT-NHNN, tăng cường an toàn giao dịch cho người dùng | I12: 46080 | J12: Players Movement | K12: Zalopay | L12: Feature | M12: Security / Privacy | N12: =L12&" | "&M12 -> Feature | Security / Privacy | O12: Zalopay nâng cấp bảo mật theo Thông tư 77/2025/TT-NHNN, tăng cường an toàn giao dịch cho người dùng | P12: Ứng dụng Zalopay sẽ tự động thoát hoặc dừng hoạt động và xuất hiện thông báo lý do trên màn hình để bảo vệ tài khoản và thông tin giao dịch của khách hàng nếu phát hiện thiết bị có dấu hiệu mất an toàn | Q12: 46082 | S12: Bảo mật thông tin; Tin tức | T12: 5 | U12: 5 | V12: 5 | W12: 5 | X12: =IF(G12<DATE(2026,4,30),T12*$T$1+U12*$U$1+V12*$V$1+W12*$W$1,T12*$T$2+U12*$U$2) -> 5
A13: =ROW()-3 -> 10 | B13: https://zalopay.vn/giam-den-50000d-khi-thanh-toan-home-credit-tren-zalopay-6686 | C13: =HYPERLINK(B13,O13) -> Giảm đến 50.000đ khi thanh toán Home Credit trên Zalopay | D13: ZaloPay Wesbite | E13: =VLOOKUP(X13,'Updating-Scoring'!$C$2:$D$7,2,TRUE) -> 5 - Industry disruption | F13: =WEEKNUM(G13,2) -> 9 | G13: 46082 | H13: Giảm đến 50.000đ khi thanh toán Home Credit trên Zalopay | I13: 46081 | J13: Players Movement | K13: Zalopay | L13: Marketing | M13: Ecosystem expansion | N13: =L13&" | "&M13 -> Marketing | Ecosystem expansion | O13: Giảm đến 50.000đ khi thanh toán Home Credit trên Zalopay | P13: Chương trình này cho thấy ZaloPay đang đẩy mạnh nhóm dịch vụ thanh toán tài chính – trả góp (FECredit, Home Credit). Việc yêu cầu mức thanh toán tối thiểu (500.000đ hoặc 1.000.000đ) giúp ZaloPay tăng giá trị giao dịch bình quân | Q13: 46054 | R13: 46112 | S13: Khuyến mãi; Ưu đãi thanh toán hóa đơn; Vay tiêu dùng; Dịch vụ vay tiêu dùng | T13: 5 | U13: 5 | V13: 5 | W13: 5 | X13: =IF(G13<DATE(2026,4,30),T13*$T$1+U13*$U$1+V13*$V$1+W13*$W$1,T13*$T$2+U13*$U$2) -> 5 | Y13: Tín dụng | Z13: Home Credit
A14: =ROW()-3 -> 11 | B14: https://zalopay.vn/giam-den-50000d-khi-thanh-toan-fe-credit-tren-zalopay-6941 | C14: =HYPERLINK(B14,O14) -> Giảm đến 50.000đ khi thanh toán FE Credit trên Zalopay | D14: ZaloPay Wesbite | E14: =VLOOKUP(X14,'Updating-Scoring'!$C$2:$D$7,2,TRUE) -> 5 - Industry disruption | F14: =WEEKNUM(G14,2) -> 9 | G14: 46082 | H14: Giảm đến 50.000đ khi thanh toán FE Credit trên Zalopay | I14: 46081 | J14: Players Movement | K14: Zalopay | L14: Marketing | M14: Ecosystem expansion | N14: =L14&" | "&M14 -> Marketing | Ecosystem expansion | O14: Giảm đến 50.000đ khi thanh toán FE Credit trên Zalopay | Q14: 46054 | R14: 46112 | S14: Khuyến mãi; Ưu đãi thanh toán hóa đơn; Vay tiêu dùng; Dịch vụ vay tiêu dùng | T14: 5 | U14: 5 | V14: 5 | W14: 5 | X14: =IF(G14<DATE(2026,4,30),T14*$T$1+U14*$U$1+V14*$V$1+W14*$W$1,T14*$T$2+U14*$U$2) -> 5 | Y14: Tín dụng | Z14: FE Credit
A15: =ROW()-3 -> 12 | B15: https://www.facebook.com/share/p/18EGxQ3xRn/?mibextid=wwXIfr | C15: =HYPERLINK(B15,O15) -> Đặt dịch vụ giao hàng SPX Express trên ZaloPay | D15: ZaloPay Fanpage | E15: =VLOOKUP(X15,'Updating-Scoring'!$C$2:$D$7,2,TRUE) -> 5 - Industry disruption | F15: =WEEKNUM(G15,2) -> 9 | G15: 46082 | H15: Đặt dịch vụ giao hàng SPX Express trên ZaloPay | I15: 46078 | J15: Players Movement | K15: Zalopay | L15: Marketing | M15: Ecosystem expansion | N15: =L15&" | "&M15 -> Marketing | Ecosystem expansion | O15: Đặt dịch vụ giao hàng SPX Express trên ZaloPay | P15: Truyền thông về dịch vụ đặt giao hàng của SPX trên ứng dụng Zalopay với giá ưu đãi hơn, từ 5.000đ/kg | Q15: 46078 | R15: 46095 | S15: Khuyến mãi; Ưu đãi thanh toán hóa đơn; Chuyển phát nhanh | T15: 5 | U15: 5 | V15: 5 | W15: 5 | X15: =IF(G15<DATE(2026,4,30),T15*$T$1+U15*$U$1+V15*$V$1+W15*$W$1,T15*$T$2+U15*$U$2) -> 5 | Y15: Thanh toán | Z15: SPX Express
A16: =ROW()-3 -> 13 | B16: https://www.momo.vn/tin-tuc/tin-tuc-su-kien/15h-17h59-23-02-giat-li-xi-mung-7-115000-bao-li-8491 | C16: =HYPERLINK(B16,O16) -> Giật Lì Xì Mùng 7: 115.000 bao lì xì đến 28k - 68k - 888k! | D16: MoMo Website | E16: =VLOOKUP(X16,'Updating-Scoring'!$C$2:$D$7,2,TRUE) -> 5 - Industry disruption | F16: =WEEKNUM(G16,2) -> 9 | G16: 46082 | H16: Giật Lì Xì Mùng 7: 115.000 bao lì xì đến 28k - 68k - 888k! | I16: 46066 | J16: Players Movement | K16: MoMo | L16: Marketing | M16: User engagement | N16: =L16&" | "&M16 -> Marketing | User engagement | O16: Giật Lì Xì Mùng 7: 115.000 bao lì xì đến 28k - 68k - 888k! | P16: Chiến dịch này tận dụng ngày Mùng 7 – thời điểm dân công sở quay lại làm việc để kích hoạt tương tác và tăng tỷ lệ mở app nối tiếp 2 chiến dịch Giật lì xì đêm Giao Thừa và Giật lì xì trong Mùng 1 Tết: - Hoàn thành nhiệm vụ “Nhận tiền từ ngân hàng về MoMo qua số điện thoại (tối thiểu 10.000đ) - 3 loại lì xì khác nhau vào 3 khung giờ khác nhau - Tổng ngân sách: 134 triệu | Q16: 46076.625 | R16: 46076.749 | S16: Khuyến mãi; Gamification; Lì xì mùng 7 | T16: 5 | U16: 5 | V16: 5 | W16: 5 | X16: =IF(G16<DATE(2026,4,30),T16*$T$1+U16*$U$1+V16*$V$1+W16*$W$1,T16*$T$2+U16*$U$2) -> 5 | Y16: Thanh toán | Z16: Nhận tiền từ ngân hàng qua SĐT Momo
A17: =ROW()-3 -> 14 | B17: https://www.momo.vn/tin-tuc/tin-tuc-su-kien/15h-17h59-26-02-giat-li-xi-ngay-than-tai-tong-8490 | C17: =HYPERLINK(B17,O17) -> Giật Lì Xì Ngày Thần Tài: Tổng hơn 879.000 bao lì xì đến 39k - 79k - 797k | D17: MoMo Website | E17: =VLOOKUP(X17,'Updating-Scoring'!$C$2:$D$7,2,TRUE) -> 5 - Industry disruption | F17: =WEEKNUM(G17,2) -> 9 | G17: 46082 | H17: Giật Lì Xì Ngày Thần Tài: Tổng hơn 879.000 bao lì xì đến 39k - 79k - 797k | I17: 46066 | J17: Players Movement | K17: MoMo | L17: Marketing | M17: User engagement | N17: =L17&" | "&M17 -> Marketing | User engagement | O17: Giật Lì Xì Ngày Thần Tài: Tổng hơn 879.000 bao lì xì đến 39k - 79k - 797k | P17: Chiến dịch đánh mạnh vào nhu cầu cầu may ngày Thần Tài từ để tăng tương tác và tỷ lệ mở app: - Hoàn thành nhiệm vụ “Kiểm tra/Chia sẻ nội dung khi kiểm tra điểm CIC trên Ứng dụng MoMo” - 6 loại lì xì khác nhau vào 6 khung giờ khác nhau - Tổng ngân sách: 265 triệu | Q17: 46079.625 | R17: 46079.874 | S17: Khuyến mãi; Gamification; Lì xì ngày thần tài | T17: 5 | U17: 5 | V17: 5 | W17: 5 | X17: =IF(G17<DATE(2026,4,30),T17*$T$1+U17*$U$1+V17*$V$1+W17*$W$1,T17*$T$2+U17*$U$2) -> 5 | Y17: Tín dụng | Z17: Kiểm tra CIC
A18: =ROW()-3 -> 15 | B18: https://www.momo.vn/tin-tuc/tin-tuc-su-kien/11h-15h-25-02-27-02-than-tai-li-xi-den-797979d-8498 | C18: =HYPERLINK(B18,O18) -> Thần Tài lì xì đến 797.979đ cùng hàng chục miếng vàng đến nửa chỉ tại Lắc Xì cùng quà Samsung tại FPTShop | D18: MoMo Website | E18: =VLOOKUP(X18,'Updating-Scoring'!$C$2:$D$7,2,TRUE) -> 5 - Industry disruption | F18: =WEEKNUM(G18,2) -> 9 | G18: 46082 | H18: Thần Tài lì xì đến 797.979đ cùng hàng chục miếng vàng đến nửa chỉ tại Lắc Xì | I18: 46078 | J18: Players Movement | K18: MoMo | L18: Marketing | M18: User engagement | N18: =L18&" | "&M18 -> Marketing | User engagement | O18: Thần Tài lì xì đến 797.979đ cùng hàng chục miếng vàng đến nửa chỉ tại Lắc Xì cùng quà Samsung tại FPTShop | P18: Chuỗi sự kiện đặc biệt nằm trong chiến dịch "Lắc xì 2026 - Săn Mã Rước Lộc" nhằm thu hút người dùng vào ứng dụng, sử dụng các sản phẩm dịch vụ của MoMo và đối tác để hoàn thành nhiệm vụ và thêm lượt giật lì xì - Nhận tiền chuyển từ ngân hàng vào MoMo bằng số điện thoại - Kiểm tra điểm CIC trên Ứng dụng MoMo - Đăng ký hội viên Nestle... | Q18: 46078.458 | R18: 46080.625 | S18: Sự kiện; Gamification; Lắc xì; Đối tác | T18: 5 | U18: 5 | V18: 5 | W18: 5 | X18: =IF(G18<DATE(2026,4,30),T18*$T$1+U18*$U$1+V18*$V$1+W18*$W$1,T18*$T$2+U18*$U$2) -> 5
